<?xml version="1.0"?>
<robot name="simplecar" xmlns:xacro="http://www.ros.org/wiki/xacro">

    <material name="black">
        <color rgba="0 0 0 1" />
    </material>
    <material name="blue">
        <color rgba="0.6 0.7 0.8 0.7" />
    </material>

    <!-- <link name="base_footprint" />

    <joint name="base_footprint_joint" type="fixed">
        <origin xyz="0 0 0" rpy="0 0 0" />
        <parent link="base_footprint" />
        <child link="base_link" />
    </joint> -->

    <!-- Base Frame of Car -->
    <link name="base_link">
        <!-- <pose>0 0 0.1 0 0 0</pose>
        <inertial>
            <mass value="15.0" />
            <origin xyz="0.0 0 0" rpy=" 0 0 0" />
            <inertia ixx="0.1" ixy="0" ixz="0" iyy="0.1" iyz="0" izz="0.1" />
        </inertial> -->
        <collision name="base_link_collision">
            <geometry>
                <box size="0.5 0.3 0.1" />
            </geometry>
        </collision>

        <visual name="base_link_visual">
            <geometry>
                <box size="0.5 0.3 0.1" />
            </geometry>
            <material name="blue" />
        </visual>
    </link>

    <!-- Left Front Wheel -->
    <link name="left_front_wheel">
        <!-- <pose>0 0 0 0 0 0</pose>
        <inertial>
            <mass value="5.0" />
            <origin xyz="0.0 0 0" rpy=" 0 1.5707 1.5707" />
            <inertia ixx="0.1" ixy="0" ixz="0" iyy="0.1" iyz="0" izz="0.1" />
        </inertial> -->
        <collision name="left_front_wheel_collision">
            <geometry>
                <cylinder length="0.05" radius="0.1" />
            </geometry>
            <origin rpy="1.57075 1.57075 0" />
            <material name="black" />
        </collision>

        <visual name="left_front_wheel_visual">
            <geometry>
                <cylinder length="0.05" radius="0.1" />
            </geometry>
            <origin rpy="1.57075 1.57075 0" />
            <material name="black" />
        </visual>
    </link>
    <joint name="left_hinge_to_left_front_wheel" type="continuous">
        <parent link="left_hinge" />
        <child link="left_front_wheel" />
        <axis xyz="0 1 0" />
        <origin xyz="0 0.2 0" />
        <!-- <limit effort="10000" velocity="1000" />
        <dynamics damping="1.0" friction="1.0" /> -->
    </joint>
    <!-- Left Front Wheel - Hinge -->
    <link name="left_hinge">
        <collision name="left_hinge_collision">
            <geometry>
                <box size="0.20 0.02 0.02" />
            </geometry>
            <origin xyz="0 0.1 0 " rpy="0 0 1.57075" />
            <material name="black" />
        </collision>

        <visual name="left_hinge_visual">
            <geometry>
                <box size="0.20 0.02 0.02" />
            </geometry>
            <origin xyz="0 0.1 0 " rpy="0 0 1.57075" />
            <material name="black" />
        </visual>
    </link>
    <joint name="base_to_left_hinge" type="revolute">
        <parent link="base_link" />
        <child link="left_hinge" />
        <axis xyz="0 0 1" />
        <origin xyz="0.2 0.0 0" />
        <limit effort="100" lower="-0.5" upper="0.5" velocity="100" />
        <!-- <dynamics damping="1.0" friction="1.0" /> -->
    </joint>
    <!-- Right Front Wheel -->
    <link name="right_front_wheel">
        <collision name="right_front_wheel_collision">
            <geometry>
                <cylinder length="0.05" radius="0.1" />
            </geometry>
            <origin rpy="-1.57075 -1.57075 0" />
            <material name="black" />
        </collision>
        <visual name="right_front_wheel_visual">
            <geometry>
                <cylinder length="0.05" radius="0.1" />
            </geometry>
            <origin rpy="-1.57075 -1.57075 0" />
            <material name="black" />
        </visual>
    </link>
    <joint name="right_hinge_to_right_front_wheel" type="continuous">
        <parent link="right_hinge" />
        <child link="right_front_wheel" />
        <axis xyz="0 1 0" />
        <origin xyz="0 -0.2 0" />
        <!-- <limit effort="10000" velocity="1000" />
        <dynamics damping="1.0" friction="1.0" /> -->
    </joint>
    <!-- Right Front Wheel - Hinge -->
    <link name="right_hinge">
        <collision name="right_hinge_collision">
            <geometry>
                <box size="0.20 0.02 0.02" />
            </geometry>
            <origin xyz="0 -0.1 0 " rpy="0 0 -1.57075" />
            <material name="black" />
        </collision>
        <visual name="right_hinge_visual">
            <geometry>
                <box size="0.20 0.02 0.02" />
            </geometry>
            <origin xyz="0 -0.1 0 " rpy="0 0 -1.57075" />
            <material name="black" />
        </visual>
    </link>
    <joint name="base_to_right_hinge" type="revolute">
        <parent link="base_link" />
        <child link="right_hinge" />
        <axis xyz="0 0 1" />
        <origin xyz="0.2 0 0" />
        <limit effort="100" lower="-0.5" upper="0.5" velocity="100" />
    </joint>

    <!-- Left Back Wheel -->
    <link name="left_back_wheel">
        <collision name="left_back_wheel_collision">
            <geometry>
                <cylinder length="0.05" radius="0.1" />
            </geometry>
            <origin rpy="1.57075 1.57075 0" />
            <material name="black" />
        </collision>
        <visual name="left_back_wheel_visual">
            <geometry>
                <cylinder length="0.05" radius="0.1" />
            </geometry>
            <origin rpy="1.57075 1.57075 0" />
            <material name="black" />
        </visual>
    </link>
    <joint name="base_to_left_back_wheel" type="continuous">
        <parent link="base_link" />
        <child link="left_back_wheel" />
        <axis xyz="0 1 0" />
        <origin xyz="-0.2 0.175 0" />
    </joint>
    <!-- Right Back Wheel -->
    <link name="right_back_wheel">
        <collision name="right_back_wheel_collision">
            <geometry>
                <cylinder length="0.05" radius="0.1" />
            </geometry>
            <origin rpy="-1.57075 -1.57075 0" />
            <material name="black" />
        </collision>
        <visual name="right_back_wheel_visual">
            <geometry>
                <cylinder length="0.05" radius="0.1" />
            </geometry>
            <origin rpy="-1.57075 -1.57075 0" />
            <material name="black" />
        </visual>
    </link>
    <joint name="base_to_right_back_wheel" type="continuous">
        <parent link="base_link" />
        <child link="right_back_wheel" />
        <axis xyz="0 1 0" />
        <origin xyz="-0.2 -0.175 0" />
    </joint>


    <!-- gazebo plugins for control and odometry ground truth-->
    <gazebo>
        <plugin name="gazebo_ros_control" filename="libgazebo_ros_control.so" />
        <plugin name="gazebo_ros_p3d" filename="libgazebo_ros_p3d.so">
            <frameName>map</frameName>
            <bodyName>base_link</bodyName>
            <topicName>odom_truth</topicName>
            <updateRate>30.0</updateRate>
        </plugin>
    </gazebo>

</robot>